Workbook
Name ListeReferences: 'Base produits'!$B$5:$B$91

Sheet Tableau de bord
A1: E.S.S. — Suivi commercial des cartouches & toners
A2: Base de travail créée à partir des deux PDF fournis · génération du 04/10/2026 · montants confirmés FCFA HT.
B5: Références actives (uniques) | C5: =COUNTA('Base produits'!$B$5:$B$91) | E5: À vérifier avant utilisation commerciale
B6: Références avec achat renseigné | C6: =COUNT('Base produits'!$H$5:$H$91) | E6: • Type déclaré : original (selon votre réponse). Toutefois, certains coûts d’achat sont très inférieurs aux prix de vente d’origine du catalogue ESS (ex. HP85A : 3 500 F vs 38 000 F; HP26A : 8 000 F vs 75 000 F). Vérifier SKU, conditionnement et authenticité avant de vendre comme original.
B7: Prix vente client à saisir | C7: =COUNTBLANK('Base produits'!$J$5:$J$91) | E7: • HP44A figure deux fois : 5 000 F et 5 500 F. Le premier tarif est affiché en prix principal; le second est conservé à côté. À confirmer.
B8: Ventes HT enregistrées | C8: =SUM(Ventes!$I$5:$I$504) | E8: • La source ne donne aucun prix d’achat pour les références 93 à 102; elles ont été exclues de la base principale conformément à votre choix.
B9: Marge brute estimée HT | C9: =SUM(Ventes!$J$5:$J$504) | E9: • Plusieurs suffixes N/C et codes proches ont été interprétés comme noir/cyan pour faciliter le repérage; confirmer les codes fabricant sur les boîtes.
B10: Références exclues (prix d’achat manquant) | C10: 10 | E10: • Les photos sont des images Web indicatives, pas une preuve que le produit en stock est identique ou authentique. Les sources sont cliquables dans l’onglet Catalogue visuel.
B11: Visuels trouvés (indicatifs) | C11: =COUNTIF('Catalogue visuel'!$H$5:$H$91,"Ouvrir la source")
B12: Visuels à ajouter | C12: =COUNTBLANK('Catalogue visuel'!$H$5:$H$91)
B15: Démarrage rapide
B16: 1 | C16: Dans « Base produits », saisissez vos prix client dans les cellules jaunes; le champ est laissé vide exprès, selon votre choix de fixation manuelle.
B17: 2 | C17: Saisissez le stock constaté au départ dans « Stock initial ». Le stock théorique se calcule ensuite à partir des réceptions et des ventes.
B18: 3 | C18: Enregistrez les achats/réceptions dans « Réceptions » et les opérations clients dans « Ventes ». Les références sont disponibles dans les listes déroulantes.
B19: 4 | C19: Utilisez « Catalogue visuel » pour consulter les photos; les cellules jaunes signalent les références pour lesquelles une photo fiable reste à ajouter.
B21: Onglets : Base produits (filtrable) · Catalogue visuel · Ventes · Réceptions · Tarifs ESS · Guide & contrôles.

Sheet Base produits
A1: E.S.S. — Base produits cartouches & toners
A2: Coûts issus de « Prix imprimante.pdf » · FCFA HT confirmés · prix de vente client à renseigner manuellement · filtrer avec les flèches des en-têtes.
A4: Fiche visuelle | B4: Référence (source) | C4: Marque | D4: Famille | E4: Couleur / variante | F4: Désignation | G4: Nature déclarée | H4: Prix achat HT | I4: Autre prix achat repéré | J4: Prix vente client HT — à saisir | K4: Repère tarif ESS HT | L4: Source du repère ESS | M4: Marge brute HT | N4: Marge % sur vente | O4: Stock initial | P4: Entrées | Q4: Sorties | R4: Stock théorique | S4: Contrôle / note | T4: Source achat
A5: Ouvrir photo | B5: HP85A | C5: HP | D5: Cartouche / toner imprimante | E5: Non précisée dans la source | F5: Cartouche/toner HP — HP85A (couleur à préciser) | G5: Original (selon votre confirmation) | H5: 3500 | K5: 38000 | L5: INF-009 — HP 85A / CE285A, correspondance exacte | M5: =IF(OR(J5="",H5=""),"",J5-H5) | N5: =IF(OR(J5="",H5="",J5=0),"",M5/J5) | P5: =SUMIF('Réceptions'!$C$5:$C$504,$B5,'Réceptions'!$E$5:$E$504) | Q5: =SUMIF('Ventes'!$D$5:$D$504,$B5,'Ventes'!$F$5:$F$504) | R5: =IF(O5="","",O5+P5-Q5) | S5: Écart très marqué entre coût d’achat et tarif de vente catalogue ESS; confirmer SKU et authenticité avant de publier un prix « original ». | T5: n°1 p.1
A6: Ouvrir photo | B6: HP83A | C6: HP | D6: Cartouche / toner imprimante | E6: Non précisée dans la source | F6: Cartouche/toner HP — HP83A (couleur à préciser) | G6: Original (selon votre confirmation) | H6: 3500 | M6: =IF(OR(J6="",H6=""),"",J6-H6) | N6: =IF(OR(J6="",H6="",J6=0),"",M6/J6) | P6: =SUMIF('Réceptions'!$C$5:$C$504,$B6,'Réceptions'!$E$5:$E$504) | Q6: =SUMIF('Ventes'!$D$5:$D$504,$B6,'Ventes'!$F$5:$F$504) | R6: =IF(O6="","",O6+P6-Q6) | S6: Prix de vente et stock initial à compléter. | T6: n°2 p.1
A7: Ouvrir photo | B7: HP35A | C7: HP | D7: Cartouche / toner imprimante | E7: Non précisée dans la source | F7: Cartouche/toner HP — HP35A (couleur à préciser) | G7: Original (selon votre confirmation) | H7: 4000 | M7: =IF(OR(J7="",H7=""),"",J7-H7) | N7: =IF(OR(J7="",H7="",J7=0),"",M7/J7) | P7: =SUMIF('Réceptions'!$C$5:$C$504,$B7,'Réceptions'!$E$5:$E$504) | Q7: =SUMIF('Ventes'!$D$5:$D$504,$B7,'Ventes'!$F$5:$F$504) | R7: =IF(O7="","",O7+P7-Q7) | S7: Prix de vente et stock initial à compléter. | T7: n°3 p.1
A8: Ouvrir photo | B8: HP36 | C8: HP | D8: Cartouche / toner imprimante | E8: Non précisée dans la source | F8: Cartouche/toner HP — HP36 (couleur à préciser) | G8: Original (selon votre confirmation) | H8: 4000 | M8: =IF(OR(J8="",H8=""),"",J8-H8) | N8: =IF(OR(J8="",H8="",J8=0),"",M8/J8) | P8: =SUMIF('Réceptions'!$C$5:$C$504,$B8,'Réceptions'!$E$5:$E$504) | Q8: =SUMIF('Ventes'!$D$5:$D$504,$B8,'Ventes'!$F$5:$F$504) | R8: =IF(O8="","",O8+P8-Q8) | S8: La photo trouvée correspond à HP 36A / CB436A; le suffixe A est absent dans le PDF source. | T8: n°4 p.1
A9: Ouvrir photo | B9: HP78A | C9: HP | D9: Cartouche / toner imprimante | E9: Non précisée dans la source | F9: Cartouche/toner HP — HP78A (couleur à préciser) | G9: Original (selon votre confirmation) | H9: 4000 | M9: =IF(OR(J9="",H9=""),"",J9-H9) | N9: =IF(OR(J9="",H9="",J9=0),"",M9/J9) | P9: =SUMIF('Réceptions'!$C$5:$C$504,$B9,'Réceptions'!$E$5:$E$504) | Q9: =SUMIF('Ventes'!$D$5:$D$504,$B9,'Ventes'!$F$5:$F$504) | R9: =IF(O9="","",O9+P9-Q9) | S9: Prix de vente et stock initial à compléter. | T9: n°5 p.1
A10: Ouvrir photo | B10: HP79A | C10: HP | D10: Cartouche / toner imprimante | E10: Non précisée dans la source | F10: Cartouche/toner HP — HP79A (couleur à préciser) | G10: Original (selon votre confirmation) | H10: 4500 | M10: =IF(OR(J10="",H10=""),"",J10-H10) | N10: =IF(OR(J10="",H10="",J10=0),"",M10/J10) | P10: =SUMIF('Réceptions'!$C$5:$C$504,$B10,'Réceptions'!$E$5:$E$504) | Q10: =SUMIF('Ventes'!$D$5:$D$504,$B10,'Ventes'!$F$5:$F$504) | R10: =IF(O10="","",O10+P10-Q10) | S10: Prix de vente et stock initial à compléter. | T10: n°6 p.1
A11: Ouvrir photo | B11: HP05A | C11: HP | D11: Cartouche / toner imprimante | E11: Non précisée dans la source | F11: Cartouche/toner HP — HP05A (couleur à préciser) | G11: Original (selon votre confirmation) | H11: 5000 | M11: =IF(OR(J11="",H11=""),"",J11-H11) | N11: =IF(OR(J11="",H11="",J11=0),"",M11/J11) | P11: =SUMIF('Réceptions'!$C$5:$C$504,$B11,'Réceptions'!$E$5:$E$504) | Q11: =SUMIF('Ventes'!$D$5:$D$504,$B11,'Ventes'!$F$5:$F$504) | R11: =IF(O11="","",O11+P11-Q11) | S11: Prix de vente et stock initial à compléter. | T11: n°7 p.1
A12: Ouvrir photo | B12: HP12A | C12: HP | D12: Cartouche / toner imprimante | E12: Non précisée dans la source | F12: Cartouche/toner HP — HP12A (couleur à préciser) | G12: Original (selon votre confirmation) | H12: 4000 | M12: =IF(OR(J12="",H12=""),"",J12-H12) | N12: =IF(OR(J12="",H12="",J12=0),"",M12/J12) | P12: =SUMIF('Réceptions'!$C$5:$C$504,$B12,'Réceptions'!$E$5:$E$504) | Q12: =SUMIF('Ventes'!$D$5:$D$504,$B12,'Ventes'!$F$5:$F$504) | R12: =IF(O12="","",O12+P12-Q12) | S12: Prix de vente et stock initial à compléter. | T12: n°8 p.1
A13: Ouvrir photo | B13: HP106A | C13: HP | D13: Cartouche / toner imprimante | E13: Non précisée dans la source | F13: Cartouche/toner HP — HP106A (couleur à préciser) | G13: Original (selon votre confirmation) | H13: 6000 | M13: =IF(OR(J13="",H13=""),"",J13-H13) | N13: =IF(OR(J13="",H13="",J13=0),"",M13/J13) | P13: =SUMIF('Réceptions'!$C$5:$C$504,$B13,'Réceptions'!$E$5:$E$504) | Q13: =SUMIF('Ventes'!$D$5:$D$504,$B13,'Ventes'!$F$5:$F$504) | R13: =IF(O13="","",O13+P13-Q13) | S13: Prix de vente et stock initial à compléter. | T13: n°9 p.1
A14: Ouvrir photo | B14: HP107A | C14: HP | D14: Cartouche / toner imprimante | E14: Non précisée dans la source | F14: Cartouche/toner HP — HP107A (couleur à préciser) | G14: Original (selon votre confirmation) | H14: 6000 | M14: =IF(OR(J14="",H14=""),"",J14-H14) | N14: =IF(OR(J14="",H14="",J14=0),"",M14/J14) | P14: =SUMIF('Réceptions'!$C$5:$C$504,$B14,'Réceptions'!$E$5:$E$504) | Q14: =SUMIF('Ventes'!$D$5:$D$504,$B14,'Ventes'!$F$5:$F$504) | R14: =IF(O14="","",O14+P14-Q14) | S14: Prix de vente et stock initial à compléter. | T14: n°10 p.1
A15: Ouvrir photo | B15: HP135A | C15: HP | D15: Cartouche / toner imprimante | E15: Non précisée dans la source | F15: Cartouche/toner HP — HP135A (couleur à préciser) | G15: Original (selon votre confirmation) | H15: 13000 | M15: =IF(OR(J15="",H15=""),"",J15-H15) | N15: =IF(OR(J15="",H15="",J15=0),"",M15/J15) | P15: =SUMIF('Réceptions'!$C$5:$C$504,$B15,'Réceptions'!$E$5:$E$504) | Q15: =SUMIF('Ventes'!$D$5:$D$504,$B15,'Ventes'!$F$5:$F$504) | R15: =IF(O15="","",O15+P15-Q15) | S15: Prix de vente et stock initial à compléter. | T15: n°11 p.1
A16: Ouvrir photo | B16: HP26A | C16: HP | D16: Cartouche / toner imprimante | E16: Non précisée dans la source | F16: Cartouche/toner HP — HP26A (couleur à préciser) | G16: Original (selon votre confirmation) | H16: 8000 | K16: 75000 | L16: INF-008 — HP 26A / CF226A, correspondance exacte | M16: =IF(OR(J16="",H16=""),"",J16-H16) | N16: =IF(OR(J16="",H16="",J16=0),"",M16/J16) | P16: =SUMIF('Réceptions'!$C$5:$C$504,$B16,'Réceptions'!$E$5:$E$504) | Q16: =SUMIF('Ventes'!$D$5:$D$504,$B16,'Ventes'!$F$5:$F$504) | R16: =IF(O16="","",O16+P16-Q16) | S16: Écart très marqué entre coût d’achat et tarif de vente catalogue ESS; confirmer SKU et authenticité avant de publier un prix « original ». | T16: n°12 p.1
A17: Ouvrir photo | B17: HP44A | C17: HP | D17: Cartouche / toner imprimante | E17: Non précisée dans la source | F17: Cartouche/toner HP — HP44A (couleur à préciser) | G17: Original (selon votre confirmation) | H17: 5000 | I17: 5500 | M17: =IF(OR(J17="",H17=""),"",J17-H17) | N17: =IF(OR(J17="",H17="",J17=0),"",M17/J17) | P17: =SUMIF('Réceptions'!$C$5:$C$504,$B17,'Réceptions'!$E$5:$E$504) | Q17: =SUMIF('Ventes'!$D$5:$D$504,$B17,'Ventes'!$F$5:$F$504) | R17: =IF(O17="","",O17+P17-Q17) | S17: Doublon source avec deux coûts : n°13 = 5 000 F; n°61 = 5 500 F. Les deux sont conservés; le premier est affiché en coût principal. | T17: n°13 p.1; n°61 p.2
A18: Ouvrir photo | B18: HP201N | C18: HP | D18: Cartouche / toner imprimante | E18: Noir (suffixe N à confirmer) | F18: Cartouche/toner HP — HP201N (noir) | G18: Original (selon votre confirmation) | H18: 7500 | M18: =IF(OR(J18="",H18=""),"",J18-H18) | N18: =IF(OR(J18="",H18="",J18=0),"",M18/J18) | P18: =SUMIF('Réceptions'!$C$5:$C$504,$B18,'Réceptions'!$E$5:$E$504) | Q18: =SUMIF('Ventes'!$D$5:$D$504,$B18,'Ventes'!$F$5:$F$504) | R18: =IF(O18="","",O18+P18-Q18) | S18: Prix de vente et stock initial à compléter. | T18: n°14 p.1
A19: Ouvrir photo | B19: HP201C | C19: HP | D19: Cartouche / toner imprimante | E19: Cyan/couleur (suffixe C à confirmer) | F19: Cartouche/toner HP — HP201C (cyan / couleur) | G19: Original (selon votre confirmation) | H19: 7500 | M19: =IF(OR(J19="",H19=""),"",J19-H19) | N19: =IF(OR(J19="",H19="",J19=0),"",M19/J19) | P19: =SUMIF('Réceptions'!$C$5:$C$504,$B19,'Réceptions'!$E$5:$E$504) | Q19: =SUMIF('Ventes'!$D$5:$D$504,$B19,'Ventes'!$F$5:$F$504) | R19: =IF(O19="","",O19+P19-Q19) | S19: Prix de vente et stock initial à compléter. | T19: n°15 p.1
A20: Ouvrir photo | B20: HP80A | C20: HP | D20: Cartouche / toner imprimante | E20: Non précisée dans la source | F20: Cartouche/toner HP — HP80A (couleur à préciser) | G20: Original (selon votre confirmation) | H20: 5000 | M20: =IF(OR(J20="",H20=""),"",J20-H20) | N20: =IF(OR(J20="",H20="",J20=0),"",M20/J20) | P20: =SUMIF('Réceptions'!$C$5:$C$504,$B20,'Réceptions'!$E$5:$E$504) | Q20: =SUMIF('Ventes'!$D$5:$D$504,$B20,'Ventes'!$F$5:$F$504) | R20: =IF(O20="","",O20+P20-Q20) | S20: Prix de vente et stock initial à compléter. | T20: n°16 p.1
A21: Ouvrir photo | B21: HP90A | C21: HP | D21: Cartouche / toner imprimante | E21: Non précisée dans la source | F21: Cartouche/toner HP — HP90A (couleur à préciser) | G21: Original (selon votre confirmation) | H21: 17000 | M21: =IF(OR(J21="",H21=""),"",J21-H21) | N21: =IF(OR(J21="",H21="",J21=0),"",M21/J21) | P21: =SUMIF('Réceptions'!$C$5:$C$504,$B21,'Réceptions'!$E$5:$E$504) | Q21: =SUMIF('Ventes'!$D$5:$D$504,$B21,'Ventes'!$F$5:$F$504) | R21: =IF(O21="","",O21+P21-Q21) | S21: Prix de vente et stock initial à compléter. | T21: n°17 p.1
A22: Ouvrir photo | B22: HP17A | C22: HP | D22: Cartouche / toner imprimante | E22: Non précisée dans la source | F22: Cartouche/toner HP — HP17A (couleur à préciser) | G22: Original (selon votre confirmation) | H22: 5000 | M22: =IF(OR(J22="",H22=""),"",J22-H22) | N22: =IF(OR(J22="",H22="",J22=0),"",M22/J22) | P22: =SUMIF('Réceptions'!$C$5:$C$504,$B22,'Réceptions'!$E$5:$E$504) | Q22: =SUMIF('Ventes'!$D$5:$D$504,$B22,'Ventes'!$F$5:$F$504) | R22: =IF(O22="","",O22+P22-Q22) | S22: Prix de vente et stock initial à compléter. | T22: n°18 p.1
A23: Ouvrir photo | B23: HP30A | C23: HP | D23: Cartouche / toner imprimante | E23: Non précisée dans la source | F23: Cartouche/toner HP — HP30A (couleur à préciser) | G23: Original (selon votre confirmation) | H23: 6000 | M23: =IF(OR(J23="",H23=""),"",J23-H23) | N23: =IF(OR(J23="",H23="",J23=0),"",M23/J23) | P23: =SUMIF('Réceptions'!$C$5:$C$504,$B23,'Réceptions'!$E$5:$E$504) | Q23: =SUMIF('Ventes'!$D$5:$D$504,$B23,'Ventes'!$F$5:$F$504) | R23: =IF(O23="","",O23+P23-Q23) | S23: Prix de vente et stock initial à compléter. | T23: n°19 p.1
A24: Ouvrir photo | B24: HP150A | C24: HP | D24: Cartouche / toner imprimante | E24: Non précisée dans la source | F24: Cartouche/toner HP — HP150A (couleur à préciser) | G24: Original (selon votre confirmation) | H24: 9000 | M24: =IF(OR(J24="",H24=""),"",J24-H24) | N24: =IF(OR(J24="",H24="",J24=0),"",M24/J24) | P24: =SUMIF('Réceptions'!$C$5:$C$504,$B24,'Réceptions'!$E$5:$E$504) | Q24: =SUMIF('Ventes'!$D$5:$D$504,$B24,'Ventes'!$F$5:$F$504) | R24: =IF(O24="","",O24+P24-Q24) | S24: Prix de vente et stock initial à compléter. | T24: n°20 p.1
A25: Ouvrir photo | B25: HP151A | C25: HP | D25: Cartouche / toner imprimante | E25: Non précisée dans la source | F25: Cartouche/toner HP — HP151A (couleur à préciser) | G25: Original (selon votre confirmation) | H25: 14000 | M25: =IF(OR(J25="",H25=""),"",J25-H25) | N25: =IF(OR(J25="",H25="",J25=0),"",M25/J25) | P25: =SUMIF('Réceptions'!$C$5:$C$504,$B25,'Réceptions'!$E$5:$E$504) | Q25: =SUMIF('Ventes'!$D$5:$D$504,$B25,'Ventes'!$F$5:$F$504) | R25: =IF(O25="","",O25+P25-Q25) | S25: Prix de vente et stock initial à compléter. | T25: n°21 p.1
A26: Ouvrir photo | B26: HP59A | C26: HP | D26: Cartouche / toner imprimante | E26: Non précisée dans la source | F26: Cartouche/toner HP — HP59A (couleur à préciser) | G26: Original (selon votre confirmation) | H26: 15000 | M26: =IF(OR(J26="",H26=""),"",J26-H26) | N26: =IF(OR(J26="",H26="",J26=0),"",M26/J26) | P26: =SUMIF('Réceptions'!$C$5:$C$504,$B26,'Réceptions'!$E$5:$E$504) | Q26: =SUMIF('Ventes'!$D$5:$D$504,$B26,'Ventes'!$F$5:$F$504) | R26: =IF(O26="","",O26+P26-Q26) | S26: Prix de vente et stock initial à compléter. | T26: n°22 p.1
A27: Ouvrir photo | B27: HP205N | C27: HP | D27: Cartouche / toner imprimante | E27: Noir (suffixe N à confirmer) | F27: Cartouche/toner HP — HP205N (noir) | G27: Original (selon votre confirmation) | H27: 7500 | K27: 45000 | L27: INF-007 — HP 205A noir / CF530A; famille proche, à confirmer | M27: =IF(OR(J27="",H27=""),"",J27-H27) | N27: =IF(OR(J27="",H27="",J27=0),"",M27/J27) | P27: =SUMIF('Réceptions'!$C$5:$C$504,$B27,'Réceptions'!$E$5:$E$504) | Q27: =SUMIF('Ventes'!$D$5:$D$504,$B27,'Ventes'!$F$5:$F$504) | R27: =IF(O27="","",O27+P27-Q27) | S27: Écart très marqué entre coût d’achat et tarif de vente catalogue ESS; confirmer SKU et authenticité avant de publier un prix « original ». | T27: n°23 p.1
A28: Ouvrir photo | B28: HP205C | C28: HP | D28: Cartouche / toner imprimante | E28: Cyan/couleur (suffixe C à confirmer) | F28: Cartouche/toner HP — HP205C (cyan / couleur) | G28: Original (selon votre confirmation) | H28: 7500 | M28: =IF(OR(J28="",H28=""),"",J28-H28) | N28: =IF(OR(J28="",H28="",J28=0),"",M28/J28) | P28: =SUMIF('Réceptions'!$C$5:$C$504,$B28,'Réceptions'!$E$5:$E$504) | Q28: =SUMIF('Ventes'!$D$5:$D$504,$B28,'Ventes'!$F$5:$F$504) | R28: =IF(O28="","",O28+P28-Q28) | S28: Prix de vente et stock initial à compléter. | T28: n°24 p.1
A29: Ouvrir photo | B29: HP203N | C29: HP | D29: Cartouche / toner imprimante | E29: Noir (suffixe N à confirmer) | F29: Cartouche/toner HP — HP203N (noir) | G29: Original (selon votre confirmation) | H29: 7500 | K29: 52000 | L29: INF-006 — HP 203A noir / CF540A; famille proche, à confirmer | M29: =IF(OR(J29="",H29=""),"",J29-H29) | N29: =IF(OR(J29="",H29="",J29=0),"",M29/J29) | P29: =SUMIF('Réceptions'!$C$5:$C$504,$B29,'Réceptions'!$E$5:$E$504) | Q29: =SUMIF('Ventes'!$D$5:$D$504,$B29,'Ventes'!$F$5:$F$504) | R29: =IF(O29="","",O29+P29-Q29) | S29: Écart très marqué entre coût d’achat et tarif de vente catalogue ESS; confirmer SKU et authenticité avant de publier un prix « original ». | T29: n°25 p.1
A30: Ouvrir photo | B30: HP203C | C30: HP | D30: Cartouche / toner imprimante | E30: Cyan/couleur (suffixe C à confirmer) | F30: Cartouche/toner HP — HP203C (cyan / couleur) | G30: Original (selon votre confirmation) | H30: 7500 | M30: =IF(OR(J30="",H30=""),"",J30-H30) | N30: =IF(OR(J30="",H30="",J30=0),"",M30/J30) | P30: =SUMIF('Réceptions'!$C$5:$C$504,$B30,'Réceptions'!$E$5:$E$504) | Q30: =SUMIF('Ventes'!$D$5:$D$504,$B30,'Ventes'!$F$5:$F$504) | R30: =IF(O30="","",O30+P30-Q30) | S30: Prix de vente et stock initial à compléter. | T30: n°26 p.1
A31: Ouvrir photo | B31: HP206N | C31: HP | D31: Cartouche / toner imprimante | E31: Noir (suffixe N à confirmer) | F31: Cartouche/toner HP — HP206N (noir) | G31: Original (selon votre confirmation) | H31: 14000 | M31: =IF(OR(J31="",H31=""),"",J31-H31) | N31: =IF(OR(J31="",H31="",J31=0),"",M31/J31) | P31: =SUMIF('Réceptions'!$C$5:$C$504,$B31,'Réceptions'!$E$5:$E$504) | Q31: =SUMIF('Ventes'!$D$5:$D$504,$B31,'Ventes'!$F$5:$F$504) | R31: =IF(O31="","",O31+P31-Q31) | S31: Prix de vente et stock initial à compléter. | T31: n°27 p.1
A32: Ouvrir photo | B32: HP206C | C32: HP | D32: Cartouche / toner imprimante | E32: Cyan/couleur (suffixe C à confirmer) | F32: Cartouche/toner HP — HP206C (cyan / couleur) | G32: Original (selon votre confirmation) | H32: 14000 | M32: =IF(OR(J32="",H32=""),"",J32-H32) | N32: =IF(OR(J32="",H32="",J32=0),"",M32/J32) | P32: =SUMIF('Réceptions'!$C$5:$C$504,$B32,'Réceptions'!$E$5:$E$504) | Q32: =SUMIF('Ventes'!$D$5:$D$504,$B32,'Ventes'!$F$5:$F$504) | R32: =IF(O32="","",O32+P32-Q32) | S32: Prix de vente et stock initial à compléter. | T32: n°28 p.1
A33: Ouvrir photo | B33: HP207N | C33: HP | D33: Cartouche / toner imprimante | E33: Noir (suffixe N à confirmer) | F33: Cartouche/toner HP — HP207N (noir) | G33: Original (selon votre confirmation) | H33: 13000 | M33: =IF(OR(J33="",H33=""),"",J33-H33) | N33: =IF(OR(J33="",H33="",J33=0),"",M33/J33) | P33: =SUMIF('Réceptions'!$C$5:$C$504,$B33,'Réceptions'!$E$5:$E$504) | Q33: =SUMIF('Ventes'!$D$5:$D$504,$B33,'Ventes'!$F$5:$F$504) | R33: =IF(O33="","",O33+P33-Q33) | S33: Prix de vente et stock initial à compléter. | T33: n°29 p.1
A34: Ouvrir photo | B34: HP207C | C34: HP | D34: Cartouche / toner imprimante | E34: Cyan/couleur (suffixe C à confirmer) | F34: Cartouche/toner HP — HP207C (cyan / couleur) | G34: Original (selon votre confirmation) | H34: 13000 | M34: =IF(OR(J34="",H34=""),"",J34-H34) | N34: =IF(OR(J34="",H34="",J34=0),"",M34/J34) | P34: =SUMIF('Réceptions'!$C$5:$C$504,$B34,'Réceptions'!$E$5:$E$504) | Q34: =SUMIF('Ventes'!$D$5:$D$504,$B34,'Ventes'!$F$5:$F$504) | R34: =IF(O34="","",O34+P34-Q34) | S34: Prix de vente et stock initial à compléter. | T34: n°30 p.1
A35: Ouvrir photo | B35: HP216N | C35: HP | D35: Cartouche / toner imprimante | E35: Noir (suffixe N à confirmer) | F35: Cartouche/toner HP — HP216N (noir) | G35: Original (selon votre confirmation) | H35: 11000 | M35: =IF(OR(J35="",H35=""),"",J35-H35) | N35: =IF(OR(J35="",H35="",J35=0),"",M35/J35) | P35: =SUMIF('Réceptions'!$C$5:$C$504,$B35,'Réceptions'!$E$5:$E$504) | Q35: =SUMIF('Ventes'!$D$5:$D$504,$B35,'Ventes'!$F$5:$F$504) | R35: =IF(O35="","",O35+P35-Q35) | S35: Prix de vente et stock initial à compléter. | T35: n°31 p.1
A36: Ouvrir photo | B36: HP216C | C36: HP | D36: Cartouche / toner imprimante | E36: Cyan/couleur (suffixe C à confirmer) | F36: Cartouche/toner HP — HP216C (cyan / couleur) | G36: Original (selon votre confirmation) | H36: 11000 | M36: =IF(OR(J36="",H36=""),"",J36-H36) | N36: =IF(OR(J36="",H36="",J36=0),"",M36/J36) | P36: =SUMIF('Réceptions'!$C$5:$C$504,$B36,'Réceptions'!$E$5:$E$504) | Q36: =SUMIF('Ventes'!$D$5:$D$504,$B36,'Ventes'!$F$5:$F$504) | R36: =IF(O36="","",O36+P36-Q36) | S36: Prix de vente et stock initial à compléter. | T36: n°32 p.1
A37: Ouvrir photo | B37: HP230N | C37: HP | D37: Cartouche / toner imprimante | E37: Noir (suffixe N à confirmer) | F37: Cartouche/toner HP — HP230N (noir) | G37: Original (selon votre confirmation) | H37: 18000 | M37: =IF(OR(J37="",H37=""),"",J37-H37) | N37: =IF(OR(J37="",H37="",J37=0),"",M37/J37) | P37: =SUMIF('Réceptions'!$C$5:$C$504,$B37,'Réceptions'!$E$5:$E$504) | Q37: =SUMIF('Ventes'!$D$5:$D$504,$B37,'Ventes'!$F$5:$F$504) | R37: =IF(O37="","",O37+P37-Q37) | S37: Prix de vente et stock initial à compléter. | T37: n°33 p.1
A38: Ouvrir photo | B38: HP230C | C38: HP | D38: Cartouche / toner imprimante | E38: Cyan/couleur (suffixe C à confirmer) | F38: Cartouche/toner HP — HP230C (cyan / couleur) | G38: Original (selon votre confirmation) | H38: 18000 | M38: =IF(OR(J38="",H38=""),"",J38-H38) | N38: =IF(OR(J38="",H38="",J38=0),"",M38/J38) | P38: =SUMIF('Réceptions'!$C$5:$C$504,$B38,'Réceptions'!$E$5:$E$504) | Q38: =SUMIF('Ventes'!$D$5:$D$504,$B38,'Ventes'!$F$5:$F$504) | R38: =IF(O38="","",O38+P38-Q38) | S38: Prix de vente et stock initial à compléter. | T38: n°34 p.1
A39: Ouvrir photo | B39: HP222N | C39: HP | D39: Cartouche / toner imprimante | E39: Noir (suffixe N à confirmer) | F39: Cartouche/toner HP — HP222N (noir) | G39: Original (selon votre confirmation) | H39: 18000 | M39: =IF(OR(J39="",H39=""),"",J39-H39) | N39: =IF(OR(J39="",H39="",J39=0),"",M39/J39) | P39: =SUMIF('Réceptions'!$C$5:$C$504,$B39,'Réceptions'!$E$5:$E$504) | Q39: =SUMIF('Ventes'!$D$5:$D$504,$B39,'Ventes'!$F$5:$F$504) | R39: =IF(O39="","",O39+P39-Q39) | S39: Prix de vente et stock initial à compléter. | T39: n°35 p.1
A40: Ouvrir photo | B40: HP222C | C40: HP | D40: Cartouche / toner imprimante | E40: Cyan/couleur (suffixe C à confirmer) | F40: Cartouche/toner HP — HP222C (cyan / couleur) | G40: Original (selon votre confirmation) | H40: 18000 | M40: =IF(OR(J40="",H40=""),"",J40-H40) | N40: =IF(OR(J40="",H40="",J40=0),"",M40/J40) | P40: =SUMIF('Réceptions'!$C$5:$C$504,$B40,'Réceptions'!$E$5:$E$504) | Q40: =SUMIF('Ventes'!$D$5:$D$504,$B40,'Ventes'!$F$5:$F$504) | R40: =IF(O40="","",O40+P40-Q40) | S40: Prix de vente et stock initial à compléter. | T40: n°36 p.1
A41: Ouvrir photo | B41: HP125N | C41: HP | D41: Cartouche / toner imprimante | E41: Noir (suffixe N à confirmer) | F41: Cartouche/toner HP — HP125N (noir) | G41: Original (selon votre confirmation) | H41: 7500 | M41: =IF(OR(J41="",H41=""),"",J41-H41) | N41: =IF(OR(J41="",H41="",J41=0),"",M41/J41) | P41: =SUMIF('Réceptions'!$C$5:$C$504,$B41,'Réceptions'!$E$5:$E$504) | Q41: =SUMIF('Ventes'!$D$5:$D$504,$B41,'Ventes'!$F$5:$F$504) | R41: =IF(O41="","",O41+P41-Q41) | S41: Prix de vente et stock initial à compléter. | T41: n°37 p.1
...

Sheet Catalogue visuel
A1: Catalogue visuel — cartouches & toners
A2: Visuels indicatifs trouvés en ligne; les liens de source sont fournis. Une photo en ligne n’atteste pas que le stock réel est original ou identique.
A4: Référence | B4: Photo | C4: Désignation | D4: Prix achat HT | E4: Repère ESS HT | F4: Prix vente client HT | G4: Statut / note visuel | H4: Source image Web
A5: HP85A | C5: Cartouche/toner HP — HP85A (couleur à préciser) | D5: 3500 | E5: 38000 | G5: Photo Web du modèle / gamme — Photo du modèle fabricant HP 85A / CE285A. | H5: Ouvrir la source
A6: HP83A | C6: Cartouche/toner HP — HP83A (couleur à préciser) | D6: 3500 | G6: Photo Web du modèle / gamme — Photo du modèle HP 83A / CF283A; annonce indiquée Genuine. | H6: Ouvrir la source
A7: HP35A | C7: Cartouche/toner HP — HP35A (couleur à préciser) | D7: 4000 | G7: Photo Web du modèle / gamme — Photo HP 35A / CB435A, annoncée Genuine OEM. | H7: Ouvrir la source
A8: HP36 | C8: Cartouche/toner HP — HP36 (couleur à préciser) | D8: 4000 | G8: Visuel de famille / équivalence — à vérifier — Visuel HP 36A / CB436A; le PDF indique HP36 sans suffixe A. | H8: Ouvrir la source
A9: HP78A | C9: Cartouche/toner HP — HP78A (couleur à préciser) | D9: 4000 | G9: Photo Web du modèle / gamme — Photo HP 78A / CE278A. | H9: Ouvrir la source
A10: HP79A | C10: Cartouche/toner HP — HP79A (couleur à préciser) | D10: 4500 | G10: Photo Web du modèle / gamme — Photo HP 79A / CF279A, annoncé Genuine. | H10: Ouvrir la source
A11: HP05A | C11: Cartouche/toner HP — HP05A (couleur à préciser) | D11: 5000 | G11: Photo Web du modèle / gamme — Photo HP 05A / CE505A original. | H11: Ouvrir la source
A12: HP12A | C12: Cartouche/toner HP — HP12A (couleur à préciser) | D12: 4000 | G12: Photo Web du modèle / gamme — Photo HP 12A / Q2612A, annoncée Genuine OEM Original. | H12: Ouvrir la source
A13: HP106A | C13: Cartouche/toner HP — HP106A (couleur à préciser) | D13: 6000 | G13: Photo Web du modèle / gamme — Visuel trouvé sous HP 106A / W1106A; vérifier le conditionnement réel. | H13: Ouvrir la source
A14: HP107A | C14: Cartouche/toner HP — HP107A (couleur à préciser) | D14: 6000 | G14: Photo Web du modèle / gamme — Photo HP 107A / W1107A. | H14: Ouvrir la source
A15: HP135A | C15: Cartouche/toner HP — HP135A (couleur à préciser) | D15: 13000 | G15: Photo Web du modèle / gamme — Photo HP 135A / W1350A; série 135A. | H15: Ouvrir la source
A16: HP26A | C16: Cartouche/toner HP — HP26A (couleur à préciser) | D16: 8000 | E16: 75000 | G16: Photo Web du modèle / gamme — Photo HP 26A / CF226A. | H16: Ouvrir la source
A17: HP44A | C17: Cartouche/toner HP — HP44A (couleur à préciser) | D17: 5000 | G17: Photo Web du modèle / gamme — Photo HP 44A / CF244A. | H17: Ouvrir la source
A18: HP201N | C18: Cartouche/toner HP — HP201N (noir) | D18: 7500 | G18: Visuel OEM de gamme/couleur — suffixe source à confirmer — Visuel HP 201A noire / CF400A (suffixe N de la source interprété Noir). | H18: Ouvrir la source
A19: HP201C | C19: Cartouche/toner HP — HP201C (cyan / couleur) | D19: 7500 | G19: Visuel OEM de gamme/couleur — suffixe source à confirmer — Visuel HP 201A Cyan / CF401A (suffixe C de la source interprété Cyan). | H19: Ouvrir la source
A20: HP80A | C20: Cartouche/toner HP — HP80A (couleur à préciser) | D20: 5000 | G20: Photo Web du modèle / gamme — Photo HP 80A / CF280A; emballage illustré, vérifier le lot réel. | H20: Ouvrir la source
A21: HP90A | C21: Cartouche/toner HP — HP90A (couleur à préciser) | D21: 17000 | G21: Photo Web du modèle / gamme — Photo HP 90A / CE390A; annonce Genuine, boîte ouverte. | H21: Ouvrir la source
A22: HP17A | C22: Cartouche/toner HP — HP17A (couleur à préciser) | D22: 5000 | G22: Photo Web du modèle / gamme — Photo HP 17A / CF217A, Genuine OEM Original. | H22: Ouvrir la source
A23: HP30A | C23: Cartouche/toner HP — HP30A (couleur à préciser) | D23: 6000 | G23: Photo Web du modèle / gamme — Photo HP 30A / CF230A. | H23: Ouvrir la source
A24: HP150A | C24: Cartouche/toner HP — HP150A (couleur à préciser) | D24: 9000 | G24: Photo Web du modèle / gamme — Photo HP 150A / W1500A. | H24: Ouvrir la source
A25: HP151A | C25: Cartouche/toner HP — HP151A (couleur à préciser) | D25: 14000 | G25: Photo Web du modèle / gamme — Photo HP 151A / W1510A. | H25: Ouvrir la source
A26: HP59A | C26: Cartouche/toner HP — HP59A (couleur à préciser) | D26: 15000 | G26: Photo Web du modèle / gamme — Photo HP 59A / CF259A, Genuine. | H26: Ouvrir la source
A27: HP205N | C27: Cartouche/toner HP — HP205N (noir) | D27: 7500 | E27: 45000 | G27: Visuel OEM de gamme/couleur — suffixe source à confirmer — Visuel HP 205A noire / CF530A (suffixe N de la source interprété Noir). | H27: Ouvrir la source
A28: HP205C | C28: Cartouche/toner HP — HP205C (cyan / couleur) | D28: 7500 | G28: Visuel OEM de gamme/couleur — suffixe source à confirmer — Visuel HP 205A Cyan / CF531A (suffixe C interprété Cyan). | H28: Ouvrir la source
A29: HP203N | C29: Cartouche/toner HP — HP203N (noir) | D29: 7500 | E29: 52000 | G29: Visuel OEM de gamme/couleur — suffixe source à confirmer — Visuel HP 203A noire / CF540A (suffixe N interprété Noir). | H29: Ouvrir la source
A30: HP203C | C30: Cartouche/toner HP — HP203C (cyan / couleur) | D30: 7500 | G30: Visuel OEM de gamme/couleur — suffixe source à confirmer — Visuel HP 203A Cyan / CF541A (suffixe C interprété Cyan). | H30: Ouvrir la source
A31: HP206N | C31: Cartouche/toner HP — HP206N (noir) | D31: 14000 | G31: Visuel OEM de gamme/couleur — suffixe source à confirmer — Visuel HP 206A noire / W2110A (suffixe N interprété Noir). | H31: Ouvrir la source
A32: HP206C | C32: Cartouche/toner HP — HP206C (cyan / couleur) | D32: 14000 | G32: Visuel OEM de gamme/couleur — suffixe source à confirmer — Visuel HP 206A Cyan (suffixe C interprété Cyan). | H32: Ouvrir la source
A33: HP207N | C33: Cartouche/toner HP — HP207N (noir) | D33: 13000 | G33: Visuel OEM de gamme/couleur — suffixe source à confirmer — Visuel HP 207A noire / W2210A. | H33: Ouvrir la source
A34: HP207C | C34: Cartouche/toner HP — HP207C (cyan / couleur) | D34: 13000 | G34: Visuel OEM de gamme/couleur — suffixe source à confirmer — Visuel HP 207A Cyan / W2211A. | H34: Ouvrir la source
A35: HP216N | C35: Cartouche/toner HP — HP216N (noir) | D35: 11000 | G35: Visuel OEM de gamme/couleur — suffixe source à confirmer — Visuel HP 216A noire / W2410A. | H35: Ouvrir la source
A36: HP216C | C36: Cartouche/toner HP — HP216C (cyan / couleur) | D36: 11000 | G36: Visuel OEM de gamme/couleur — suffixe source à confirmer — Visuel HP 216A Cyan. | H36: Ouvrir la source
A37: HP230N | C37: Cartouche/toner HP — HP230N (noir) | D37: 18000 | G37: Visuel OEM de gamme/couleur — suffixe source à confirmer — Visuel HP 230A noire / W2300A. | H37: Ouvrir la source
A38: HP230C | C38: Cartouche/toner HP — HP230C (cyan / couleur) | D38: 18000 | G38: Visuel OEM de gamme/couleur — suffixe source à confirmer — Visuel HP 230A Cyan / W2301A. | H38: Ouvrir la source
A39: HP222N | C39: Cartouche/toner HP — HP222N (noir) | D39: 18000 | G39: Visuel OEM de gamme/couleur — suffixe source à confirmer — Visuel HP 222A noire. | H39: Ouvrir la source
A40: HP222C | C40: Cartouche/toner HP — HP222C (cyan / couleur) | D40: 18000 | G40: Visuel OEM de gamme/couleur — suffixe source à confirmer — Visuel HP 222A Cyan / W2221A. | H40: Ouvrir la source
A41: HP125N | C41: Cartouche/toner HP — HP125N (noir) | D41: 7500 | G41: Visuel OEM de gamme/couleur — suffixe source à confirmer — Visuel HP 125A noire / CB540A. | H41: Ouvrir la source
...

Sheet Ventes
A1: Journal des ventes
A2: Choisir une référence; la désignation et le prix client se reprennent de « Base produits ». Renseigner d’abord le prix client sur cette base.
A4: Date | B4: N° facture | C4: Client | D4: Référence | E4: Désignation | F4: Qté | G4: Prix vente unitaire HT | H4: Remise % | I4: Total ligne HT | J4: Marge brute estimée HT | K4: Mode de paiement | L4: Note
E5: =IF($D5="","",IFERROR(VLOOKUP($D5,'Base produits'!$B$5:$F$91,5,FALSE),"")) | G5: =IF($D5="","",IFERROR(IF(VLOOKUP($D5,'Base produits'!$B$5:$J$91,9,FALSE)="","",VLOOKUP($D5,'Base produits'!$B$5:$J$91,9,FALSE)),"")) | I5: =IF(OR($D5="",$F5="",$G5=""),"",$F5*$G5*(1-IFERROR($H5,0))) | J5: =IF(OR($D5="",$F5="",$G5=""),"",($G5-IFERROR(VLOOKUP($D5,'Base produits'!$B$5:$H$91,7,FALSE),0))*$F5*(1-IFERROR($H5,0)))
E6: =IF($D6="","",IFERROR(VLOOKUP($D6,'Base produits'!$B$5:$F$91,5,FALSE),"")) | G6: =IF($D6="","",IFERROR(IF(VLOOKUP($D6,'Base produits'!$B$5:$J$91,9,FALSE)="","",VLOOKUP($D6,'Base produits'!$B$5:$J$91,9,FALSE)),"")) | I6: =IF(OR($D6="",$F6="",$G6=""),"",$F6*$G6*(1-IFERROR($H6,0))) | J6: =IF(OR($D6="",$F6="",$G6=""),"",($G6-IFERROR(VLOOKUP($D6,'Base produits'!$B$5:$H$91,7,FALSE),0))*$F6*(1-IFERROR($H6,0)))
E7: =IF($D7="","",IFERROR(VLOOKUP($D7,'Base produits'!$B$5:$F$91,5,FALSE),"")) | G7: =IF($D7="","",IFERROR(IF(VLOOKUP($D7,'Base produits'!$B$5:$J$91,9,FALSE)="","",VLOOKUP($D7,'Base produits'!$B$5:$J$91,9,FALSE)),"")) | I7: =IF(OR($D7="",$F7="",$G7=""),"",$F7*$G7*(1-IFERROR($H7,0))) | J7: =IF(OR($D7="",$F7="",$G7=""),"",($G7-IFERROR(VLOOKUP($D7,'Base produits'!$B$5:$H$91,7,FALSE),0))*$F7*(1-IFERROR($H7,0)))
E8: =IF($D8="","",IFERROR(VLOOKUP($D8,'Base produits'!$B$5:$F$91,5,FALSE),"")) | G8: =IF($D8="","",IFERROR(IF(VLOOKUP($D8,'Base produits'!$B$5:$J$91,9,FALSE)="","",VLOOKUP($D8,'Base produits'!$B$5:$J$91,9,FALSE)),"")) | I8: =IF(OR($D8="",$F8="",$G8=""),"",$F8*$G8*(1-IFERROR($H8,0))) | J8: =IF(OR($D8="",$F8="",$G8=""),"",($G8-IFERROR(VLOOKUP($D8,'Base produits'!$B$5:$H$91,7,FALSE),0))*$F8*(1-IFERROR($H8,0)))
E9: =IF($D9="","",IFERROR(VLOOKUP($D9,'Base produits'!$B$5:$F$91,5,FALSE),"")) | G9: =IF($D9="","",IFERROR(IF(VLOOKUP($D9,'Base produits'!$B$5:$J$91,9,FALSE)="","",VLOOKUP($D9,'Base produits'!$B$5:$J$91,9,FALSE)),"")) | I9: =IF(OR($D9="",$F9="",$G9=""),"",$F9*$G9*(1-IFERROR($H9,0))) | J9: =IF(OR($D9="",$F9="",$G9=""),"",($G9-IFERROR(VLOOKUP($D9,'Base produits'!$B$5:$H$91,7,FALSE),0))*$F9*(1-IFERROR($H9,0)))
E10: =IF($D10="","",IFERROR(VLOOKUP($D10,'Base produits'!$B$5:$F$91,5,FALSE),"")) | G10: =IF($D10="","",IFERROR(IF(VLOOKUP($D10,'Base produits'!$B$5:$J$91,9,FALSE)="","",VLOOKUP($D10,'Base produits'!$B$5:$J$91,9,FALSE)),"")) | I10: =IF(OR($D10="",$F10="",$G10=""),"",$F10*$G10*(1-IFERROR($H10,0))) | J10: =IF(OR($D10="",$F10="",$G10=""),"",($G10-IFERROR(VLOOKUP($D10,'Base produits'!$B$5:$H$91,7,FALSE),0))*$F10*(1-IFERROR($H10,0)))
E11: =IF($D11="","",IFERROR(VLOOKUP($D11,'Base produits'!$B$5:$F$91,5,FALSE),"")) | G11: =IF($D11="","",IFERROR(IF(VLOOKUP($D11,'Base produits'!$B$5:$J$91,9,FALSE)="","",VLOOKUP($D11,'Base produits'!$B$5:$J$91,9,FALSE)),"")) | I11: =IF(OR($D11="",$F11="",$G11=""),"",$F11*$G11*(1-IFERROR($H11,0))) | J11: =IF(OR($D11="",$F11="",$G11=""),"",($G11-IFERROR(VLOOKUP($D11,'Base produits'!$B$5:$H$91,7,FALSE),0))*$F11*(1-IFERROR($H11,0)))
E12: =IF($D12="","",IFERROR(VLOOKUP($D12,'Base produits'!$B$5:$F$91,5,FALSE),"")) | G12: =IF($D12="","",IFERROR(IF(VLOOKUP($D12,'Base produits'!$B$5:$J$91,9,FALSE)="","",VLOOKUP($D12,'Base produits'!$B$5:$J$91,9,FALSE)),"")) | I12: =IF(OR($D12="",$F12="",$G12=""),"",$F12*$G12*(1-IFERROR($H12,0))) | J12: =IF(OR($D12="",$F12="",$G12=""),"",($G12-IFERROR(VLOOKUP($D12,'Base produits'!$B$5:$H$91,7,FALSE),0))*$F12*(1-IFERROR($H12,0)))
E13: =IF($D13="","",IFERROR(VLOOKUP($D13,'Base produits'!$B$5:$F$91,5,FALSE),"")) | G13: =IF($D13="","",IFERROR(IF(VLOOKUP($D13,'Base produits'!$B$5:$J$91,9,FALSE)="","",VLOOKUP($D13,'Base produits'!$B$5:$J$91,9,FALSE)),"")) | I13: =IF(OR($D13="",$F13="",$G13=""),"",$F13*$G13*(1-IFERROR($H13,0))) | J13: =IF(OR($D13="",$F13="",$G13=""),"",($G13-IFERROR(VLOOKUP($D13,'Base produits'!$B$5:$H$91,7,FALSE),0))*$F13*(1-IFERROR($H13,0)))
E14: =IF($D14="","",IFERROR(VLOOKUP($D14,'Base produits'!$B$5:$F$91,5,FALSE),"")) | G14: =IF($D14="","",IFERROR(IF(VLOOKUP($D14,'Base produits'!$B$5:$J$91,9,FALSE)="","",VLOOKUP($D14,'Base produits'!$B$5:$J$91,9,FALSE)),"")) | I14: =IF(OR($D14="",$F14="",$G14=""),"",$F14*$G14*(1-IFERROR($H14,0))) | J14: =IF(OR($D14="",$F14="",$G14=""),"",($G14-IFERROR(VLOOKUP($D14,'Base produits'!$B$5:$H$91,7,FALSE),0))*$F14*(1-IFERROR($H14,0)))
E15: =IF($D15="","",IFERROR(VLOOKUP($D15,'Base produits'!$B$5:$F$91,5,FALSE),"")) | G15: =IF($D15="","",IFERROR(IF(VLOOKUP($D15,'Base produits'!$B$5:$J$91,9,FALSE)="","",VLOOKUP($D15,'Base produits'!$B$5:$J$91,9,FALSE)),"")) | I15: =IF(OR($D15="",$F15="",$G15=""),"",$F15*$G15*(1-IFERROR($H15,0))) | J15: =IF(OR($D15="",$F15="",$G15=""),"",($G15-IFERROR(VLOOKUP($D15,'Base produits'!$B$5:$H$91,7,FALSE),0))*$F15*(1-IFERROR($H15,0)))
E16: =IF($D16="","",IFERROR(VLOOKUP($D16,'Base produits'!$B$5:$F$91,5,FALSE),"")) | G16: =IF($D16="","",IFERROR(IF(VLOOKUP($D16,'Base produits'!$B$5:$J$91,9,FALSE)="","",VLOOKUP($D16,'Base produits'!$B$5:$J$91,9,FALSE)),"")) | I16: =IF(OR($D16="",$F16="",$G16=""),"",$F16*$G16*(1-IFERROR($H16,0))) | J16: =IF(OR($D16="",$F16="",$G16=""),"",($G16-IFERROR(VLOOKUP($D16,'Base produits'!$B$5:$H$91,7,FALSE),0))*$F16*(1-IFERROR($H16,0)))
... E504: =IF($D504="","",IFERROR(VLOOKUP($D504,'Base produits'!$B$5:$F$91,5,FALSE),"")) | G504: =IF($D504="","",IFERROR(IF(VLOOKUP($D504,'Base produits'!$B$5:$J$91,9,FALSE)="","",VLOOKUP($D504,'Base produits'!$B$5:$J$91,9,FALSE)),"")) | I504: =IF(OR($D504="",$F504="",$G504=""),"",$F504*$G504*(1-IFERROR($H504,0))) | J504: =IF(OR($D504="",$F504="",$G504=""),"",($G504-IFERROR(VLOOKUP($D504,'Base produits'!$B$5:$H$91,7,FALSE),0))*$F504*(1-IFERROR($H504,0)))

Sheet Réceptions
A1: Réceptions et entrées de stock
A2: Saisir une ligne par réception fournisseur. Le coût unitaire est prérempli depuis la base; corriger la valeur si la facture fournisseur diffère.
A4: Date | B4: Fournisseur | C4: Référence | D4: Désignation | E4: Qté reçue | F4: Prix achat unitaire HT | G4: Total achat HT | H4: Facture / note
D5: =IF($C5="","",IFERROR(VLOOKUP($C5,'Base produits'!$B$5:$F$91,5,FALSE),"")) | F5: =IF($C5="","",IFERROR(IF(VLOOKUP($C5,'Base produits'!$B$5:$H$91,7,FALSE)="","",VLOOKUP($C5,'Base produits'!$B$5:$H$91,7,FALSE)),"")) | G5: =IF(OR($C5="",$E5="",$F5=""),"",$E5*$F5)
D6: =IF($C6="","",IFERROR(VLOOKUP($C6,'Base produits'!$B$5:$F$91,5,FALSE),"")) | F6: =IF($C6="","",IFERROR(IF(VLOOKUP($C6,'Base produits'!$B$5:$H$91,7,FALSE)="","",VLOOKUP($C6,'Base produits'!$B$5:$H$91,7,FALSE)),"")) | G6: =IF(OR($C6="",$E6="",$F6=""),"",$E6*$F6)
D7: =IF($C7="","",IFERROR(VLOOKUP($C7,'Base produits'!$B$5:$F$91,5,FALSE),"")) | F7: =IF($C7="","",IFERROR(IF(VLOOKUP($C7,'Base produits'!$B$5:$H$91,7,FALSE)="","",VLOOKUP($C7,'Base produits'!$B$5:$H$91,7,FALSE)),"")) | G7: =IF(OR($C7="",$E7="",$F7=""),"",$E7*$F7)
D8: =IF($C8="","",IFERROR(VLOOKUP($C8,'Base produits'!$B$5:$F$91,5,FALSE),"")) | F8: =IF($C8="","",IFERROR(IF(VLOOKUP($C8,'Base produits'!$B$5:$H$91,7,FALSE)="","",VLOOKUP($C8,'Base produits'!$B$5:$H$91,7,FALSE)),"")) | G8: =IF(OR($C8="",$E8="",$F8=""),"",$E8*$F8)
D9: =IF($C9="","",IFERROR(VLOOKUP($C9,'Base produits'!$B$5:$F$91,5,FALSE),"")) | F9: =IF($C9="","",IFERROR(IF(VLOOKUP($C9,'Base produits'!$B$5:$H$91,7,FALSE)="","",VLOOKUP($C9,'Base produits'!$B$5:$H$91,7,FALSE)),"")) | G9: =IF(OR($C9="",$E9="",$F9=""),"",$E9*$F9)
D10: =IF($C10="","",IFERROR(VLOOKUP($C10,'Base produits'!$B$5:$F$91,5,FALSE),"")) | F10: =IF($C10="","",IFERROR(IF(VLOOKUP($C10,'Base produits'!$B$5:$H$91,7,FALSE)="","",VLOOKUP($C10,'Base produits'!$B$5:$H$91,7,FALSE)),"")) | G10: =IF(OR($C10="",$E10="",$F10=""),"",$E10*$F10)
D11: =IF($C11="","",IFERROR(VLOOKUP($C11,'Base produits'!$B$5:$F$91,5,FALSE),"")) | F11: =IF($C11="","",IFERROR(IF(VLOOKUP($C11,'Base produits'!$B$5:$H$91,7,FALSE)="","",VLOOKUP($C11,'Base produits'!$B$5:$H$91,7,FALSE)),"")) | G11: =IF(OR($C11="",$E11="",$F11=""),"",$E11*$F11)
D12: =IF($C12="","",IFERROR(VLOOKUP($C12,'Base produits'!$B$5:$F$91,5,FALSE),"")) | F12: =IF($C12="","",IFERROR(IF(VLOOKUP($C12,'Base produits'!$B$5:$H$91,7,FALSE)="","",VLOOKUP($C12,'Base produits'!$B$5:$H$91,7,FALSE)),"")) | G12: =IF(OR($C12="",$E12="",$F12=""),"",$E12*$F12)
D13: =IF($C13="","",IFERROR(VLOOKUP($C13,'Base produits'!$B$5:$F$91,5,FALSE),"")) | F13: =IF($C13="","",IFERROR(IF(VLOOKUP($C13,'Base produits'!$B$5:$H$91,7,FALSE)="","",VLOOKUP($C13,'Base produits'!$B$5:$H$91,7,FALSE)),"")) | G13: =IF(OR($C13="",$E13="",$F13=""),"",$E13*$F13)
D14: =IF($C14="","",IFERROR(VLOOKUP($C14,'Base produits'!$B$5:$F$91,5,FALSE),"")) | F14: =IF($C14="","",IFERROR(IF(VLOOKUP($C14,'Base produits'!$B$5:$H$91,7,FALSE)="","",VLOOKUP($C14,'Base produits'!$B$5:$H$91,7,FALSE)),"")) | G14: =IF(OR($C14="",$E14="",$F14=""),"",$E14*$F14)
D15: =IF($C15="","",IFERROR(VLOOKUP($C15,'Base produits'!$B$5:$F$91,5,FALSE),"")) | F15: =IF($C15="","",IFERROR(IF(VLOOKUP($C15,'Base produits'!$B$5:$H$91,7,FALSE)="","",VLOOKUP($C15,'Base produits'!$B$5:$H$91,7,FALSE)),"")) | G15: =IF(OR($C15="",$E15="",$F15=""),"",$E15*$F15)
D16: =IF($C16="","",IFERROR(VLOOKUP($C16,'Base produits'!$B$5:$F$91,5,FALSE),"")) | F16: =IF($C16="","",IFERROR(IF(VLOOKUP($C16,'Base produits'!$B$5:$H$91,7,FALSE)="","",VLOOKUP($C16,'Base produits'!$B$5:$H$91,7,FALSE)),"")) | G16: =IF(OR($C16="",$E16="",$F16=""),"",$E16*$F16)
... D504: =IF($C504="","",IFERROR(VLOOKUP($C504,'Base produits'!$B$5:$F$91,5,FALSE),"")) | F504: =IF($C504="","",IFERROR(IF(VLOOKUP($C504,'Base produits'!$B$5:$H$91,7,FALSE)="","",VLOOKUP($C504,'Base produits'!$B$5:$H$91,7,FALSE)),"")) | G504: =IF(OR($C504="",$E504="",$F504=""),"",$E504*$F504)

Sheet Tarifs ESS
A1: Repères de vente du catalogue ESS 2026
A2: Prix du catalogue général, page 12 — indicatifs et HT. Ils sont séparés des prix client saisis dans la base afin d’éviter toute association automatique incertaine.
A4: Réf. catalogue | B4: Désignation | C4: Type indiqué | D4: Conditionnement | E4: Prix catalogue HT | F4: Utilisation | G4: Source
A5: INF-006 | B5: Toner laser noir original — HP 203A (CF540A) | C5: Original | D5: Unité | E5: 52000 | F5: Repère pour HP203N noir; famille proche, confirmer la correspondance. | G5: ESS_Catalogue_General_2026.pdf, p.12
A6: INF-007 | B6: Toner laser noir original — HP 205A (CF530A) | C6: Original | D6: Unité | E6: 45000 | F6: Repère pour HP205N noir; famille proche, confirmer la correspondance. | G6: ESS_Catalogue_General_2026.pdf, p.12
A7: INF-008 | B7: Toner laser noir original — HP 26A (CF226A) | C7: Original | D7: Unité | E7: 75000 | F7: Repère HP26A; correspondance exacte de gamme. | G7: ESS_Catalogue_General_2026.pdf, p.12
A8: INF-009 | B8: Toner laser noir original — HP 85A (CE285A) | C8: Original | D8: Unité | E8: 38000 | F8: Repère HP85A; correspondance exacte de gamme. | G8: ESS_Catalogue_General_2026.pdf, p.12
A9: INF-010 | B9: Toner laser noir original — HP 84A (CF284A) | C9: Original | D9: Unité | E9: 95000 | F9: Article du catalogue; aucune référence d’achat identique dans la liste source. | G9: ESS_Catalogue_General_2026.pdf, p.12
A10: INF-011 | B10: Cartouche d’encre noire compatible (HP / Canon) | C10: Compatible | D10: Unité | E10: 8000 | F10: Tarif générique, non associé à une référence précise. | G10: ESS_Catalogue_General_2026.pdf, p.12
A11: INF-012 | B11: Cartouche d’encre couleur compatible (HP / Canon) | C11: Compatible | D11: Unité | E11: 10000 | F11: Tarif générique, non associé à une référence précise. | G11: ESS_Catalogue_General_2026.pdf, p.12
A12: INF-013 | B12: Toner laser noir compatible (Brother / Samsung / HP) | C12: Compatible | D12: Unité | E12: 15000 | F12: Tarif générique, non associé à une référence précise. | G12: ESS_Catalogue_General_2026.pdf, p.12
A13: INF-014 | B13: Cartouche photocopieur RICOH MP C3003 / 3503 | C13: À préciser | D13: Unité | F13: Sur devis. | G13: ESS_Catalogue_General_2026.pdf, p.12
A14: INF-015 | B14: Kit de maintenance / tambour | C14: À préciser | D14: Unité | F14: Sur devis. | G14: ESS_Catalogue_General_2026.pdf, p.12

Sheet Guide
A1: Guide d’utilisation & contrôles de source
A2: Ce classeur est une base de gestion, à compléter avec vos coûts confirmés, prix clients, photos réelles et stocks de départ.
B4: Périmètre | C4: Cartouches/toners et tambours tarifés dans « Prix imprimante.pdf ». 100 lignes tarifaires étaient présentes; 10 lignes sans prix d’achat ont été écartées et les doublons ont été regroupés, soit 87 références uniques avec prix.
B5: Prix d’achat | C5: Les montants de la source ont été retranscrits comme coûts d’achat unitaires. Vous avez confirmé FCFA HT. HP44A garde 5 000 F en tarif principal et 5 500 F dans « Autre prix achat repéré »; choisissez le tarif réel selon le fournisseur.
B6: Prix de vente | C6: Vous avez demandé une fixation manuelle. La colonne « Prix vente client HT » reste donc vide (cellules jaunes). Les repères ESS 2026 sont séparés dans une colonne et dans l’onglet « Tarifs ESS »; ils ne sont pas injectés automatiquement.
B7: Repères catalogue | C7: Le catalogue général page 12 affiche 5 tarifs de toners HP originaux et plusieurs prix génériques compatibles. Seuls les repères HP85A et HP26A sont mis comme correspondances exactes; HP203N/HP205N sont des correspondances de gamme à confirmer.
B8: Type original / compatible | C8: Vous avez indiqué que les références sont originales. Attention : certains prix d’achat (notamment HP85A, HP26A, HP203N et HP205N) sont très éloignés des tarifs catalogue des toners originaux. Vérifier les emballages, références fabricant et factures avant de publier ces articles comme originaux.
B9: Photos | C9: Les visuels viennent de pages Web liées dans « Catalogue visuel ». Ils sont fournis pour faciliter l’identification, pas comme preuve de la nature du stock réel. Les références sans image OEM suffisamment fiable sont marquées « Photo à ajouter ».
B10: Codes à contrôler | C10: « CEXVV28N » et « CANN047 » sont conservés tels qu’imprimés, avec une note sur leur probable orthographe. « HP36 » apparaît sans suffixe A dans le prix d’achat, alors que le visuel trouvé correspond à HP36A. Le numérotage source saute les n°53 et 54.
B11: Doublons | C11: HP44A apparaît avec deux coûts (5 000 F au n°13 et 5 500 F au n°61). HP131N et HP131C sont répétés deux fois au même tarif; une seule fiche par référence est conservée.
B12: Références écartées (prix absent) | C12: CEXV42GIGA, CEXV33GIGA, CEXV65GIGA, CEXV64, CEXV59, CEXV59GIGA, CEXV37, CEXV34, GR15, GPR18. Elles ne figurent pas dans la base principale; ajoutez-les uniquement après confirmation des prix d’achat.
B13: Stocks | C13: Entrez une valeur de départ dans « Stock initial ». Chaque réception ajoutée dans l’onglet « Réceptions » augmente le stock; chaque vente saisie dans « Ventes » le réduit. Sans stock initial, le stock théorique reste vide pour éviter d’afficher un faux zéro.
B14: Conditions catalogue | C14: Le catalogue ESS précise que les prix 2026 sont indicatifs, hors taxes, communiqués sur devis et susceptibles de remises. Les tarifs d’origine s’appliquent uniquement à la référence et à la version correspondantes.
